<!DOCTYPE html>
<html lang="en">

<head>
  <meta charset="UTF-8">
  <meta http-equiv="X-UA-Compatible" content="IE=edge">
  <meta name="viewport" content="width=device-width, initial-scale=1.0">
  <title>async异步操作</title>
</head>

<body>
  <script>
    /**
     * async  使得异步操作更加简单，是Generator的语法糖
     * async会返回一个Promise对象
    */
    async function f() {

    }
    // console.log(f());  // Promise {<fulfilled>: undefined}
    /**
     * asycn表示函数里面有异步操作
     * await表示紧跟后面的表达式需要等待执行结果
     *    await内部是then命令的语法糖
    */
    /**
     * async函数返回一个 Promise 对象，可以使用then方法添加回调函数。当函数执行的时候，一旦遇到await就会先返回，等到异步操作完成，再接着执行函数体内后面的语句。
    */
    function timeout(ms) {
      return new Promise((resolve) => {
        setTimeout(resolve, ms)
      })
    }
    async function print(value, ms) {
      await timeout(ms)
      console.log(value)
    }
    // print("hello", 1000)

    /**
     * asycn有多种使用形式
    */
    // 函数
    async function fun() { }
    // 表达式
    let foo = async function () { }
    // 对象的方法
    let obj = { async foo() { } }
    obj.foo().then()
    // class
    // 箭头函数
    const foo1 = async () => { }

    /**
     * async函数内部的return语句返回值会成为then方法回调函数的参数
    */
    async function f() {
      return "async函数内部的return语句返回值会成为then方法回调函数的参数"
    }
    f().then(v => {
      // console.log(v);
    })

    /**
     * async函数内部抛出的错误，会导致返回的Promise对象变为reject状态，抛出的错误对象会被catch方法回调函数接收到
    */
    async function fo() {
      return new Error("出错了")
    }
    fo().then(v => {
      // console.log("resolve", v);
    }).catch(err => {
      // console.log("reject", err);
    })

    /**
     * Promise对象的状态变化：
     *    async函数返回的Promise对象，必须等到内部所有await命令后面的Promise对象执行完，状态才会发生改变，除非遇到return或者抛出错误。
     *    即：只有async函数内部的异步操作执行完，才会执行then方法指定的回调函数。
    */
    async function getTitle(url) {
      let response = await fetch(url)
      let html = await response.text()
      return html.match(/<title>([\s\S]+)<\/title>/i)[1]
    }
    // getTitle('https://tc39.github.io/ecma262/').then()
    // 上面代码中，函数getTitle内部有三个操作：抓取网页、取出文本、匹配页面标题。只有这三个操作全部完成，才会执行then方法里面的代码


    /**
     * await命令：正常情况下，await命令后面是一个Promise对象，返回该对象的结果。如果不是Promise对象，就直接返回对应的值
    */
   async function fn() {
    return await 123  // ===> 等同于return 123
   }
   fn().then(res => {
    // console.log(res);  // 123
   })
   /**
    * 另一种情况，await后面是一个定义了then方法的对象，那么await会将其等同于Promise对象
   */
   class Sleep {
    constructor(timeout){
      this.timeout = timeout
    }
    then(resolve, reject){
      const startTime = Date.now()
      setTimeout(
        () => resolve(Date.now() - startTime),
        this.timeout
      )
    }
   }
   (async () => {
    const sleepTime = await new Sleep(1000)
    // console.log(sleepTime)  // 1000
   })() 
   // 上面代码中，await命令后面是一个Sleep对象的实例。这个实例不是Promise对象，但是因为定义了then方法，await会将其视为Promis处理。

   /**
    * await命令后面的Promise对象如果变为reject状态，则reject参数会被catch方法的回调函数接收到
   */
   async function fu() {
    await Promise.reject("error!!!!")
    // return await Promise.reject("errrrrr!!!!")
   }
   fu().then(res => {
    // console.log(res);
   }).catch(err => {
    // console.log(err);
   })
   // 上面代码中，await语句前面没有return，但是reject方法的参数依然传入了catch方法的回调函数。上面如果给await加上return，效果是一样的。

   /**
    * 任何一个await语句后面的 Promise 对象变为reject状态，那么整个async函数都会中断执行。
   */
  async function func(){
    await Promise.reject("出错了")
    return await Promise.resolve("hello world")
  }
  func().then(res => {
    // console.log(res);
  }).catch(err => {
    // console.log(err);
  })  // 出错了

  // 有时候我们需要前一个异步操作失败，也不要中断后面的异步操作。这时候可以将第一个await放在try...catch中，这样不管第一个异步操作是否成功，第二个await都会执行
  async function funct(){
    try{
      await Promise.reject("error!!!")
    }catch(err){

    }
    return await Promise.resolve("hello world")
  }
  funct().then(res => {
    // console.log(res);  // hello world
  })
  </script>
</body>

</html>